<?xml version="1.0" ?>
<!-- =================================================================================== -->
<!-- |    This document was autogenerated by xacro from xacro/wheelwalker_v1.urdf.xacro | -->
<!-- |    EDITING THIS FILE BY HAND IS NOT RECOMMENDED                                 | -->
<!-- =================================================================================== -->
<robot name="wheelwalker_v1">

  <link name="base_link">
    <visual>
      <geometry>
        <mesh filename="../meshes/wheelwalker_v0.1/base_link.stl"/>
      </geometry>
      <origin rpy="0 0 0" xyz="0 0 0.0"/>
      <material name="LightGrey">
        <color rgba="0.6 0.6 0.6 1.0"/>
      </material>
    </visual>
    <collision>
      <origin rpy="0 0 0" xyz="0 0 0.0"/>
      <geometry>
        <box size="0.49500000000000005 0.44000000000000006 0.385"/>
      </geometry>
    </collision>
    <inertial>
      <origin rpy="0 0 0" xyz="0 0 0.0"/>
      <mass value="6.0396"/>
      <inertia ixx="0.14218225" ixy="0.0" ixz="0.0" iyy="0.1635725" iyz="0.0" izz="0.18244625"/>
    </inertial>
  </link>


  <!-- shoulder mounting points -->
  <joint name="top_shoulder_mount_joint" type="fixed">
    <origin rpy="0 0 0" xyz="0.12600000000000003 0.0 0.175"/>
    <parent link="base_link"/>
    <child link="top_shoulder_mount_link"/>
  </joint>
  <link name="top_shoulder_mount_link">
    <visual>
      <origin rpy="0 0 0" xyz="0 0 0"/>
      <geometry>
        <cylinder length="0.08879999999999999" radius="0.0185"/>
      </geometry>
      <material name="yellow-skin">
        <color rgba="1.0 0.7 0.0 1.0"/>
      </material>    </visual>
  </link>

  <!-- Left Leg Links -->
  <!-- hip mounting points -->
  <joint name="left_hip_mount_joint" type="fixed">
    <origin rpy="0 0 0" xyz="0.0 0.119 -0.147"/>
    <parent link="base_link"/>
    <child link="left_hip_yaw_link"/>
  </joint>


  <!-- hip yaw -->

  <link name="left_hip_yaw_link">
    <visual>
      <origin rpy="0 0 0" xyz="0 0 0"/>
      <geometry>
        <mesh filename="../meshes/wheelwalker_v0.1/left_hip_yaw_link.stl" scale="0.001 0.001 0.001"/>
      </geometry>
      <material name="LightGrey">
        <color rgba="0.6 0.6 0.6 1.0"/>
      </material>
    </visual>
    <collision>
      <origin rpy="0 0 0" xyz="0 0 0"/>
      <geometry>
        <cylinder length="0.08879999999999999" radius="0.0185"/>
      </geometry>
    </collision>
    <inertial>
      <origin rpy="0 0 0" xyz="0 0 0"/>
      <mass value="0.85"/>
      <inertia ixx="0.0006312801249999998" ixy="0.0" ixz="0.0" iyy="0.0006312801249999998" iyz="0.0" izz="0.00014545624999999997"/>
    </inertial>
  </link>
  <joint name="left_hip_yaw_joint" type="fixed">
    <origin rpy="0 0 0" xyz="0 0 0"/>
    <parent link="left_hip_yaw_link"/>
    <child link="left_hip_roll_link"/>
    <axis xyz="0 0 1"/>
    <limit effort="1000.0" lower="-3.14159265359" upper="3.14159265359" velocity="10.0"/>
    <dynamics damping="0.0" friction="0.0"/>
  </joint>

  <!-- hip roll -->

  <link name="left_hip_roll_link">
    <visual>
      <origin rpy="0 0 0" xyz="0 0 0.08175"/>
      <geometry>
        <mesh filename="../meshes/wheelwalker_v0.1/left_hip_roll_link.stl" scale="0.001 0.001 0.001"/>
      </geometry>
      <material name="LightGrey">
        <color rgba="0.6 0.6 0.6 1.0"/>
      </material>
    </visual>
    <collision>
      <origin rpy="0 1.570796326795 0" xyz="0 0 0.08175"/>
      <geometry>
        <cylinder length="0.08879999999999999" radius="0.0185"/>
      </geometry>
    </collision>
    <inertial>
      <origin rpy="0 1.570796326795 0" xyz="0 0 0.08175"/>
      <mass value="0.85"/>
      <inertia ixx="0.0006312801249999998" ixy="0.0" ixz="0.0" iyy="0.0006312801249999998" iyz="0.0" izz="0.00014545624999999997"/>
    </inertial>
  </link>
  <joint name="left_hip_roll_joint" type="fixed">
    <origin rpy="0 0 0" xyz="0 0 0.08175"/>
    <parent link="left_hip_roll_link"/>
    <child link="left_hip_pitch_link"/>
    <axis xyz="1 0 0"/>
    <limit effort="1000.0" lower="-3.14159265359" upper="3.14159265359" velocity="10.0"/>
    <dynamics damping="0.0" friction="0.0"/>
  </joint>

  <!-- hip pitch -->

  <link name="left_hip_pitch_link">
    <visual>
      <origin rpy="0 0 0" xyz="0 0.07525 0"/>
      <geometry>
        <mesh filename="../meshes/wheelwalker_v0.1/left_hip_pitch_link.stl" scale="0.001 0.001 0.001"/>
      </geometry>
      <material name="LightGrey">
        <color rgba="0.6 0.6 0.6 1.0"/>
      </material>
    </visual>
    <collision>
      <origin rpy="1.570796326795 0 0" xyz="0 0.07525 0"/>
      <geometry>
        <cylinder length="0.08879999999999999" radius="0.0185"/>
      </geometry>
    </collision>
    <inertial>
      <origin rpy="1.570796326795 0 0" xyz="0 0.07525 0"/>
      <mass value="0.85"/>
      <inertia ixx="0.0006312801249999998" ixy="0.0" ixz="0.0" iyy="0.0006312801249999998" iyz="0.0" izz="0.00014545624999999997"/>
    </inertial>
  </link>
  <joint name="left_hip_pitch_joint" type="fixed">
    <origin rpy="0 0 0" xyz="0 0.07525 0"/>
    <parent link="left_hip_pitch_link"/>
    <child link="left_thigh_link"/>
    <axis xyz="0 1 0"/>
    <limit effort="1000.0" lower="-1.570796326795" upper="1.570796326795" velocity="10.0"/>
    <dynamics damping="0.0" friction="0.0"/>
  </joint>

  <!-- Thigh link -->

  <link name="left_thigh_link">
    <visual>
      <origin rpy="0 0 0" xyz="0 0 0"/>
      <geometry>
        <mesh filename="../meshes/wheelwalker_v0.1/left_thigh_link.stl" scale="0.001 0.001 0.001"/>
      </geometry>
      <material name="LightGrey">
        <color rgba="0.6 0.6 0.6 1.0"/>
      </material>
    </visual>
    <collision>
      <origin rpy="0 0 0" xyz="0.0 0.0 -0.125"/>
      <geometry>
        <cylinder length="0.275" radius="0.036300000000000006"/>
      </geometry>
    </collision>
    <inertial>
      <origin rpy="0 0 0" xyz="0.0 0.0 -0.125"/>
      <mass value="2.8"/>
      <inertia ixx="0.015345633333333332" ixy="0.0" ixz="0.0" iyy="0.015345633333333332" iyz="0.0" izz="0.0015246"/>
    </inertial>
  </link>


  <joint name="left_knee_pitch_joint" type="fixed">
    <origin rpy="0 -1.570796326795 0 " xyz="0.04 0 -0.25"/>
    <parent link="left_thigh_link"/>
    <child link="left_tibia_link"/>
    <axis xyz="0 1 0"/>
    <limit effort="1000.0" lower="-0.7853981633975" upper="0.7853981633975" velocity="10.0"/>
    <dynamics damping="0.0" friction="0.0"/>
  </joint>

  <link name="left_tibia_link">
    <visual>
      <origin rpy="0 0 0" xyz="0 0 0"/>
      <geometry>
        <mesh filename="../meshes/wheelwalker_v0.1/left_tibia_link.stl" scale="0.001 0.001 0.001"/>
      </geometry>
      <material name="LightGrey">
        <color rgba="0.6 0.6 0.6 1.0"/>
      </material>
    </visual>
    <collision>
      <origin rpy="0 0 0" xyz="0 0 -0.125"/>
      <geometry>
        <cylinder length="0.275" radius="0.03465"/>
      </geometry>
    </collision>
    <inertial>
      <origin rpy="0 0 0" xyz="0 0 -0.125"/>
      <mass value="1.2"/>
      <inertia ixx="0.006547674999999999" ixy="0.0" ixz="0.0" iyy="0.006547674999999999" iyz="0.0" izz="0.00059535"/>
    </inertial>
  </link>


  <!-- supporting foot -->

  <joint name="left_ankle_pitch_joint" type="fixed">
    <origin rpy="0 1.570796326795 0" xyz="0 -0.05 -0.25"/>
    <parent link="left_tibia_link"/>
    <child link="left_foot_link"/>
    <axis xyz="0 1 0"/>
    <limit effort="1000.0" lower="-0.7853981633975" upper="0.7853981633975" velocity="10.0"/>
    <dynamics damping="0.0" friction="0.0"/>
  </joint>

  <link name="left_foot_link">
    <visual>
      <origin rpy="0 0 0" xyz="0 0 0"/>
      <geometry>
        <mesh filename="../meshes/wheelwalker_v0.1/left_foot_link.stl" scale="0.001 0.001 0.001"/>
      </geometry>
      <material name="LightGrey">
        <color rgba="0.6 0.6 0.6 1.0"/>
      </material>
    </visual>
    <collision>
      <origin rpy="0 1.570796326795 0" xyz="-0.09 0 0"/>
      <geometry>
        <cylinder length="0.18" radius="0.012"/>
      </geometry>
    </collision>
    <inertial>
      <origin rpy="0 1.570796326795 0" xyz="-0.09 0 0"/>
      <mass value="1.177"/>
      <inertia ixx="0.0032202719999999997" ixy="0.0" ixz="0.0" iyy="0.0032202719999999997" iyz="0.0" izz="8.4744e-05"/>
    </inertial>
  </link>

  <!-- wheel link -->

  <joint name="left_wheel_joint" type="revolute">
    <origin rpy="0 1.570796326795 0" xyz="0 0.05 -0.25"/>
    <parent link="left_tibia_link"/>
    <child link="left_wheel_link"/>
    <axis xyz="0 1 0"/>
    <limit effort="1000.0" velocity="10.0"/>
    <dynamics damping="0.0" friction="0.0"/>
  </joint>
  <link name="left_wheel_link">
    <visual>
      <origin rpy="0 0 0" xyz="0 0 0"/>
      <geometry>
        <mesh filename="../meshes/wheelwalker_v0.1/left_wheel_link.stl" scale="0.001 0.001 0.001"/>
      </geometry>
      <material name="LightGrey">
        <color rgba="0.6 0.6 0.6 1.0"/>
      </material>
    </visual>
    <collision>
      <origin rpy="1.570796326795 0 0" xyz="0 0 0"/>
      <geometry>
        <cylinder length="0.03" radius="0.11"/>
      </geometry>
    </collision>
    <inertial>
      <origin rpy="1.570796326795 0 0" xyz="0 0 0"/>
      <mass value="0.9"/>
      <inertia ixx="0.0027899999999999995" ixy="0.0" ixz="0.0" iyy="0.0027899999999999995" iyz="0.0" izz="0.005445"/>
    </inertial>
  </link>
  <!-- Right Leg Links -->

  <!-- hip mounting points -->

  <joint name="right_hip_mount_joint" type="fixed">
    <origin rpy="0 0 0" xyz="0.0 -0.119 -0.147"/>
    <parent link="base_link"/>
    <child link="right_hip_yaw_link"/>
  </joint>

  <!-- hip yaw -->

  <link name="right_hip_yaw_link">
    <visual>
      <origin rpy="0 0 0" xyz="0 0 0"/>
      <geometry>
        <mesh filename="../meshes/wheelwalker_v0.1/right_hip_yaw_link.stl" scale="0.001 0.001 0.001"/>
      </geometry>
      <material name="LightGrey">
        <color rgba="0.6 0.6 0.6 1.0"/>
      </material>
    </visual>
    <collision>
      <origin rpy="0 0 0" xyz="0 0 0"/>
      <geometry>
        <cylinder length="0.08879999999999999" radius="0.0185"/>
      </geometry>
    </collision>
    <inertial>
      <origin rpy="0 0 0" xyz="0 0 0"/>
      <mass value="0.85"/>
      <inertia ixx="0.0006312801249999998" ixy="0.0" ixz="0.0" iyy="0.0006312801249999998" iyz="0.0" izz="0.00014545624999999997"/>
    </inertial>
  </link>
  <joint name="right_hip_yaw_joint" type="fixed">
    <origin rpy="0 0 0" xyz="0 0 0"/>
    <parent link="right_hip_yaw_link"/>
    <child link="right_hip_roll_link"/>
    <axis xyz="0 0 1"/>
    <limit effort="1000.0" lower="-3.14159265359" upper="3.14159265359" velocity="10.0"/>
    <dynamics damping="0.0" friction="0.0"/>
  </joint>

  <!-- hip roll -->

  <link name="right_hip_roll_link">
    <visual>
      <origin rpy="0 0 0" xyz="0 0 0.08175"/>
      <geometry>
        <mesh filename="../meshes/wheelwalker_v0.1/right_hip_roll_link.stl" scale="0.001 0.001 0.001"/>
      </geometry>
      <material name="LightGrey">
        <color rgba="0.6 0.6 0.6 1.0"/>
      </material>
    </visual>
    <collision>
      <origin rpy="0 1.570796326795 0" xyz="0 0 0.08175"/>
      <geometry>
        <cylinder length="0.08879999999999999" radius="0.0185"/>
      </geometry>
    </collision>
    <inertial>
      <origin rpy="0 1.570796326795 0" xyz="0 0 0.08175"/>
      <mass value="0.85"/>
      <inertia ixx="0.0006312801249999998" ixy="0.0" ixz="0.0" iyy="0.0006312801249999998" iyz="0.0" izz="0.00014545624999999997"/>
    </inertial>
  </link>
  <joint name="right_hip_roll_joint" type="fixed">
    <origin rpy="0 0 0" xyz="0 0 0.08175"/>
    <parent link="right_hip_roll_link"/>
    <child link="right_hip_pitch_link"/>
    <axis xyz="-1 0 0"/>
    <limit effort="1000.0" lower="-3.14159265359" upper="3.14159265359" velocity="10.0"/>
    <dynamics damping="0.0" friction="0.0"/>
  </joint>

  <!-- hip pitch -->

  <link name="right_hip_pitch_link">
    <visual>
      <origin rpy="0 0 0" xyz="0 -0.07525 0"/>
      <geometry>
        <mesh filename="../meshes/wheelwalker_v0.1/right_hip_pitch_link.stl" scale="0.001 0.001 0.001"/>
      </geometry>
      <material name="LightGrey">
        <color rgba="0.6 0.6 0.6 1.0"/>
      </material>
    </visual>
    <collision>
      <origin rpy="1.570796326795 0 0" xyz="0 -0.07525 0"/>
      <geometry>
        <cylinder length="0.08879999999999999" radius="0.0185"/>
      </geometry>
    </collision>
    <inertial>
      <origin rpy="1.570796326795 0 0" xyz="0 -0.07525 0"/>
      <mass value="0.85"/>
      <inertia ixx="0.0006312801249999998" ixy="0.0" ixz="0.0" iyy="0.0006312801249999998" iyz="0.0" izz="0.00014545624999999997"/>
    </inertial>
  </link>
  <joint name="right_hip_pitch_joint" type="fixed">
    <origin rpy="0 0 0" xyz="0 -0.07525 0"/>
    <parent link="right_hip_pitch_link"/>
    <child link="right_thigh_link"/>
    <axis xyz="0 1 0"/>
    <limit effort="1000.0" lower="-1.570796326795" upper="1.570796326795" velocity="10.0"/>
    <dynamics damping="0.0" friction="0.0"/>
  </joint>

  <!-- Thigh link -->

  <link name="right_thigh_link">
    <visual>
      <origin rpy="0 0 0" xyz="0 0 0"/>
      <geometry>
        <mesh filename="../meshes/wheelwalker_v0.1/right_thigh_link.stl" scale="0.001 0.001 0.001"/>
      </geometry>
      <material name="LightGrey">
        <color rgba="0.6 0.6 0.6 1.0"/>
      </material>
    </visual>
    <collision>
      <origin rpy="0 0 0" xyz="0.0 -0.0 -0.125"/>
      <geometry>
        <cylinder length="0.275" radius="0.036300000000000006"/>
      </geometry>
    </collision>
    <inertial>
      <origin rpy="0 0 0" xyz="0.0 -0.0 -0.125"/>
      <mass value="2.8"/>
      <inertia ixx="0.015345633333333332" ixy="0.0" ixz="0.0" iyy="0.015345633333333332" iyz="0.0" izz="0.0015246"/>
    </inertial>
  </link>

  <joint name="right_knee_pitch_joint" type="fixed">
    <origin rpy="0 -1.570796326795 0 " xyz="0.04 0 -0.25"/>
    <parent link="right_thigh_link"/>
    <child link="right_tibia_link"/>
    <axis xyz="0 1 0"/>
    <limit effort="1000.0" lower="-0.7853981633975" upper="0.7853981633975" velocity="10.0"/>
    <dynamics damping="0.0" friction="0.0"/>
  </joint>

  <link name="right_tibia_link">
    <visual>
      <origin rpy="0 0 0" xyz="0 0 0"/>
      <geometry>
        <mesh filename="../meshes/wheelwalker_v0.1/right_tibia_link.stl" scale="0.001 0.001 0.001"/>
      </geometry>
      <material name="LightGrey">
        <color rgba="0.6 0.6 0.6 1.0"/>
      </material>
    </visual>
    <collision>
      <origin rpy="0 0 0" xyz="0 0 -0.125"/>
      <geometry>
        <cylinder length="0.275" radius="0.03465"/>
      </geometry>
    </collision>
    <inertial>
      <origin rpy="0 0 0" xyz="0 0 -0.125"/>
      <mass value="1.2"/>
      <inertia ixx="0.006547674999999999" ixy="0.0" ixz="0.0" iyy="0.006547674999999999" iyz="0.0" izz="0.00059535"/>
    </inertial>
  </link>

  <!-- supporting foot -->
  <joint name="right_ankle_pitch_joint" type="fixed">
    <origin rpy="0 1.570796326795 0" xyz="0 0.05 -0.25"/>
    <parent link="right_tibia_link"/>
    <child link="right_foot_link"/>
    <axis xyz="0 1 0"/>
    <limit effort="1000.0" lower="-0.7853981633975" upper="0.7853981633975" velocity="10.0"/>
    <dynamics damping="0.0" friction="0.0"/>
  </joint>
  <link name="right_foot_link">
    <visual>
      <origin rpy="0 0 0" xyz="0 0 0"/>
      <geometry>
        <mesh filename="../meshes/wheelwalker_v0.1/right_foot_link.stl" scale="0.001 0.001 0.001"/>
      </geometry>
      <material name="LightGrey">
        <color rgba="0.6 0.6 0.6 1.0"/>
      </material>
    </visual>
    <collision>
      <origin rpy="0 1.570796326795 0" xyz="-0.09 0 0"/>
      <geometry>
        <cylinder length="0.18" radius="0.012"/>
      </geometry>
    </collision>
    <inertial>
      <origin rpy="0 1.570796326795 0" xyz="-0.09 0 0"/>
      <mass value="1.177"/>
      <inertia ixx="0.0032202719999999997" ixy="0.0" ixz="0.0" iyy="0.0032202719999999997" iyz="0.0" izz="8.4744e-05"/>
    </inertial>
  </link>

  <!-- wheel link -->

  <joint name="right_wheel_joint" type="revolute">
    <origin rpy="0 1.570796326795 0" xyz="0 -0.05 -0.25"/>
    <parent link="right_tibia_link"/>
    <child link="right_wheel_link"/>
    <axis xyz="0 1 0"/>
    <limit effort="1000.0" velocity="10.0"/>
    <dynamics damping="0.0" friction="0.0"/>
  </joint>

  <link name="right_wheel_link">
    <visual>
      <origin rpy="0 0 0" xyz="0 0 0"/>
      <geometry>
        <mesh filename="../meshes/wheelwalker_v0.1/right_wheel_link.stl" scale="0.001 0.001 0.001"/>
      </geometry>
      <material name="LightGrey">
        <color rgba="0.6 0.6 0.6 1.0"/>
      </material>
    </visual>
    <collision>
      <origin rpy="1.570796326795 0 0" xyz="0 0 0"/>
      <geometry>
        <cylinder length="0.03" radius="0.11"/>
      </geometry>
    </collision>
    <inertial>
      <origin rpy="1.570796326795 0 0" xyz="0 0 0"/>
      <mass value="0.9"/>
      <inertia ixx="0.0027899999999999995" ixy="0.0" ixz="0.0" iyy="0.0027899999999999995" iyz="0.0" izz="0.005445"/>
    </inertial>
  </link>
</robot>

