<?xml version="1.0" ?>
<!-- =================================================================================== -->
<!-- |    This document was autogenerated by xacro from xacro/wheelwalker_v1.urdf.xacro | -->
<!-- |    EDITING THIS FILE BY HAND IS NOT RECOMMENDED                                 | -->
<!-- =================================================================================== -->
<robot name="wheelwalker_v1">
  <!-- The following included files set up definitions of parts of the robot body -->
  <!-- This file is not a robot in and of itself, it just contains some useful tags that could be included in any robot -->
  <!-- <xacro:include filename="$(find wheelwalker_description)/description/materials.urdf.xacro"/> -->
  <!-- Some constants -->
  <!-- Kinect Camera Location (Nominally 0) -->
  <!-- Rigid shape -->
  <!-- Detailed shape -->
  <!-- Virtual shape -->
  <!-- Mounting Points -->
  <!-- Joints -->
  <!-- Specify some standard inertial calculations https://en.wikipedia.org/wiki/List_of_moments_of_inertia -->
  <!-- These make use of xacro's mathematical functionality -->
  <!-- This file is not a robot in and of itself, it just contains some useful tags that could be included in any robot -->

  <!-- WheelWalker arm -->
  <!-- <xacro:include filename="$(find wheelwalker_description)/description/shoulder/shoulder_v1.urdf.xacro"/> -->
  <!-- <xacro:include filename="$(find wheelwalker_description)/description/upper_arm/upper_arm_v1.urdf.xacro"/> -->
  <!-- <xacro:include filename="$(find wheelwalker_description)/description/forearm/forearm_v1.urdf.xacro"/> -->
  <!-- <xacro:include filename="$(find wheelwalker_description)/description/wrist/wrist_v1.urdf.xacro"/> -->
  <!-- <xacro:include filename="$(find wheelwalker_description)/description/gripper/gripper_v1.urdf.xacro"/> -->
  <!-- WheelWalker torso -->
  <!-- <xacro:include filename="$(find wheelwalker_description)/description/torso/torso_v1.urdf.xacro"/> -->
  <!-- WheelWalker base -->
  <!-- <xacro:include filename="$(find wheelwalker_description)/description/sensors/kinect_camera.urdf.xacro"> -->
  <!-- DATA SOURCES -->
  <!-- all simplified collision geometry are hand approximated from CAD model, 
        sometime from respective bounding boxes-->
  <!-- expandable limb mounting points -->
  <!-- left hip mounting point -->
  <!-- <xacro:property name="left_hip_mount_x" value="${base_length*0.0}"/>
    <xacro:property name="left_hip_mount_y" value="0.119"/>
    <xacro:property name="left_hip_mount_z" value="-0.147"/>
    <xacro:property name="left_hip_mount_rpy" value="0 0 0"/> -->
  <!-- right hip mounting point -->
  <!-- <xacro:property name="right_hip_mount_x" value="${base_length*0.0}"/>
    <xacro:property name="right_hip_mount_y" value="-0.119"/>
    <xacro:property name="right_hip_mount_z" value="-0.147"/>
    <xacro:property name="right_hip_mount_rpy" value="0 0 0"/> -->
  <!-- tail mounting point -->
  <!-- <xacro:property name="tail_mount_x" value="-0.1852"/>
    <xacro:property name="tail_mount_y" value="${base_width*0.0}"/>
    <xacro:property name="tail_mount_z" value="-0.0653"/>
    <xacro:property name="tail_mount_rpy" value="-${PI/2} 0 0"/> -->
  <!-- Base Link -->
  <!-- joint offsets -->
  <!-- Knee mount point -->
  <!-- <xacro:property name="knee_mount_x" value="0.04"/>
    <xacro:property name="knee_mount_y" value="0"/>
    <xacro:property name="knee_mount_z" value="-${thigh_length}"/>
    <xacro:property name="knee_mount_rpy" value="${PI/2} 0 0 "/> -->
  <!-- hip macro -->
  <!-- simplified box collision geometry for hip joints -->
  <!-- <xacro:property name="thigh_length" value="0.3"/> -->
  <!-- <xacro:property name="thigh_radius" value="0.1"/> -->
  <!-- <xacro:property name="thigh_mass" value="1.0"/> -->
  <!-- mount dimensions -->
  <!-- <xacro:property name="mount_length" value="0.1"/> -->
  <!-- <xacro:property name="mount_radius" value="0.05"/> -->
  <!-- Thigh macro -->
  <!-- ankle mount point -->
  <!-- <xacro:property name="ankle_mount_x" value="0"/>
    <xacro:property name="ankle_mount_y" value="-${0.0325 - 0.03175}"/>
    <xacro:property name="ankle_mount_z" value="-${mount_radius_knee + tibia_length + mount_radius_ankle}"/>
    <xacro:property name="ankle_mount_rpy" value="${PI/2} 0 0"/> -->
  <!-- Knee macro -->
  <!-- ankle mount point -->
  <!-- <xacro:property name="ankle_mount_x" value="0"/>
    <xacro:property name="ankle_mount_y" value="-${0.0325 - 0.03175}"/>
    <xacro:property name="ankle_mount_z" value="-${mount_radius_knee + tibia_length + mount_radius_ankle}"/>
    <xacro:property name="ankle_mount_rpy" value="${PI/2} 0 0"/> -->
  <!-- ankle macro -->
  <!-- wheel macro -->
  <!-- Tail shape macro -->
  <!-- Now we can start using the macros included above to define the actual WheelWalker -->
  <link name="base_link">
    <visual>
      <geometry>
        <mesh filename="../meshes/wheelwalker_v0.1/base_link.stl"/>
      </geometry>
      <origin rpy="0 0 0" xyz="0 0 0.0"/>
      <material name="">   
        <color rgba="0.6 0.6 0.6 1.0"/>
      </material>
    </visual>

    <collision>
      <origin rpy="0 0 0" xyz="0 0 0.0"/>
      <geometry>
        <box size="0.27 0.24 0.35"/>
      </geometry>
    </collision>
    <!-- <inertial>
                <origin xyz="0 0 ${base_spawn_height}" rpy="0 0 0"/>
                <mass value="${base_mass}"/>
                <inertia ixx="0.1" ixy="0.0" ixz="0.0"
                         iyy="0.1" iyz="0.0"
                         izz="0.1" />
            </inertial> -->
    <inertial>
      <origin rpy="0 0 0" xyz="0 0 0.0"/>
      <mass value="30.198"/>
      <inertia ixx="0.71091125" ixy="0.0" ixz="0.0" iyy="0.8178624999999999" iyz="0.0" izz="0.91223125"/>
    </inertial>
  </link>
  <!-- hip mounting points -->
  <!-- <joint name="left_hip_mount_joint" type="fixed">
            <origin xyz="${left_hip_mount_x} ${left_hip_mount_y} ${left_hip_mount_z}" rpy="0 0 0"/>
            <parent link="base_link"/>
            <child link="left_hip_mount_link"/>
        </joint> -->
  <!-- <xacro:virtual_shape name="left_hip_mount_link" color="yellow-skin">
            <origin xyz="0 0 0" rpy="${left_hip_mount_rpy}"/>
            <cylinder radius="${mount_radius}" length="${mount_length}"/>
        </xacro:virtual_shape> -->
  <!-- <xacro:rigid_shape name="left_hip_mount_link" mass="1.0" color="yellow-skin">
            <origin xyz="0 0 0" rpy="${left_hip_mount_rpy}"/>
            <cylinder radius="${mount_radius}" length="${mount_length}"/>
            <inertia ixx="0.1" ixy="0.0" ixz="0.0"
                     iyy="0.1" iyz="0.0"
                     izz="0.1"/>
        </xacro:rigid_shape> -->
  <!-- <joint name="right_hip_mount_joint" type="fixed">
            <origin xyz="${right_hip_mount_x} ${right_hip_mount_y} ${right_hip_mount_z}" rpy="0 0 0"/>
            <parent link="base_link"/>
            <child link="right_hip_mount_link"/>
        </joint> -->
  <!-- <xacro:virtual_shape name="right_hip_mount_link" color="yellow-skin">
            <origin xyz="0 0 0" rpy="${right_hip_mount_rpy}"/>
            <cylinder radius="${mount_radius}" length="${mount_length}"/>
        </xacro:virtual_shape> -->
  <!-- <xacro:rigid_shape name="right_hip_mount_link" mass="1.0" color="yellow-skin">
            <origin xyz="0 0 0" rpy="${right_hip_mount_rpy}"/>
            <cylinder radius="${mount_radius}" length="${mount_length}"/>
            <inertia ixx="0.1" ixy="0.0" ixz="0.0"
                     iyy="0.1" iyz="0.0"
                     izz="0.1"/>
        </xacro:rigid_shape> -->
  <!-- <xacro:joint_mount name="left_hip_mount" 
                            parent_link="base_link" 
                            attachment_origin="${left_hip_mount_x} ${left_hip_mount_y} ${left_hip_mount_z}" 
                            attachment_rotation="${left_hip_mount_rpy}"
                            mount_radius="${mount_radius}"
                            mount_length="${mount_length}"
                            color="yellow-skin"/> -->
  <!-- <xacro:joint_mount name="right_hip_mount" 
                            parent_link="base_link" 
                            attachment_origin="${right_hip_mount_x} ${right_hip_mount_y} ${right_hip_mount_z}" 
                            attachment_rotation="${right_hip_mount_rpy}"
                            mount_radius="${mount_radius}"
                            mount_length="${mount_length}"
                            color="yellow-skin"/> -->
  <!-- shoulder mounting points -->
  <joint name="top_shoulder_mount_joint" type="fixed">
    <origin rpy="0 0 0" xyz="0.12600000000000003 0.0 0.175"/>
    <parent link="base_link"/>
    <child link="top_shoulder_mount_link"/>
  </joint>
  <link name="top_shoulder_mount_link">
    <visual>
      <origin rpy="0 0 0" xyz="0 0 0"/>
      <geometry>
        <cylinder length="0.08879999999999999" radius="0.0185"/>
      </geometry>
      <material name="">
        <color rgba="1 0.7 0 1"/>
      </material>
    </visual>
  </link>
  <!-- <xacro:rigid_shape name="top_shoulder_mount_link" mass="1.0" color="yellow-skin">
            <origin xyz="0 0 0" rpy="${top_shoulder_mount_rpy}"/>
            <cylinder radius="${mount_radius}" length="${mount_length}"/>
            <inertia ixx="0.1" ixy="0.0" ixz="0.0"
                     iyy="0.1" iyz="0.0"
                     izz="0.1"/>
        </xacro:rigid_shape> -->
  <!-- <xacro:joint_mount name="top_shoulder_mount" 
                            parent_link="base_link" 
                            attachment_origin="${top_shoulder_mount_x} ${top_shoulder_mount_y} ${top_shoulder_mount_z}" 
                            attachment_rotation="${top_shoulder_mount_rpy}"
                            mount_radius="${mount_radius}"
                            mount_length="${mount_length}"
                            color="yellow-skin"/> -->
  <!-- tail mounting points -->
  <!-- <joint name="tail_mount_joint" type="fixed">
            <origin xyz="${tail_mount_x} ${tail_mount_y} ${tail_mount_z}" rpy="0 -${PI/6} 0"/>
            <parent link="base_link"/>
            <child link="tail_mount_link"/>
        </joint> -->
  <!-- <xacro:virtual_shape name="tail_mount_link" color="yellow-skin">
            <origin xyz="0 0 0" rpy="${tail_mount_rpy}"/>
            <cylinder radius="${mount_radius}" length="${mount_length * 2}"/>
        </xacro:virtual_shape> -->
  <!-- <xacro:rigid_shape name="tail_mount_link" mass="1.0" color="yellow-skin">
            <origin xyz="0 0 0" rpy="${tail_mount_rpy}"/>
            <cylinder radius="${mount_radius}" length="${mount_length}"/>
            <inertia ixx="0.1" ixy="0.0" ixz="0.0"
                     iyy="0.1" iyz="0.0"
                     izz="0.1"/>
        </xacro:rigid_shape> -->
  <!-- <xacro:joint_mount name="tail_mount" 
                            parent_link="base_link" 
                            attachment_origin="${tail_mount_x} ${tail_mount_y} ${tail_mount_z}" 
                            attachment_rotation="${tail_mount_rpy}"
                            mount_radius="${mount_radius}"
                            mount_length="${mount_length}"
                            color="yellow-skin"/> -->
  <joint name="tail_pitch_joint" type="fixed">
    <origin rpy="0 -0.5235987755983333 0" xyz="-0.1852 0.0 -0.0653"/>
    <parent link="base_link"/>
    <child link="tail_link"/>
    <!-- <child link="${name}_pitch_link"/> -->
    <axis xyz="0 1 0"/>
    <limit effort="1000.0" lower="-1.0471975511966667" upper="0.5235987755983333" velocity="10.0"/>
    <dynamics damping="0.0" friction="0.0"/>
  </joint>
  <!-- <link name="${name}_link">

            <visual>
                <origin xyz="0 0 0" rpy="0 0 0"/>
                <geometry>
                    <mesh filename="../meshes/wheelwalker_v0.1/tail_link.STL"/>
                </geometry>
                <material name="color"/>
            </visual>

            <collision>
                <origin xyz="0 0 0" rpy="0 0 0"/>
                <geometry>
                    <box size="${tail_length} ${tail_width} ${tail_height}"/>
                </geometry>
            </collision>

            <inertial>
                <origin xyz="0 0 0" rpy="0 0 0"/>
                <mass value="${tail_mass}"/>
                <inertia ixx="0.1" ixy="0.0" ixz="0.0" 
                         iyy="0.1" iyz="0.0" 
                         izz="0.1"/>
            </inertial>

        </link> -->
  <link name="tail_link">
    <visual>
      <origin rpy="0 0.5235987755983333 0" xyz="0 0 0"/>
      <geometry>
        <mesh filename="../meshes/wheelwalker_v0.1/tail_link.stl" scale="0.001 0.001 0.001"/>
      </geometry>
      <material name="">   
        <color rgba="0.6 0.6 0.6 1.0"/>
      </material>
    </visual>

    <collision>
      <origin rpy="0 0 0" xyz="-0.139 0 0"/>
      <geometry>
        <box size="0.19 0.21 0.185"/>
      </geometry>
    </collision>
    <inertial>
      <origin rpy="0 0 0" xyz="-0.139 0 0"/>
      <mass value="8.0"/>
      <inertia ixx="0.05221666666666666" ixy="0.0" ixz="0.0" iyy="0.04688333333333333" iyz="0.0" izz="0.05346666666666666"/>
    </inertial>
    <!-- <xacro:insert_block name="inertial"/> -->
  </link>
  <!-- <xacro:rigid_shape name="${name}_link" mass="${tail_mass}" color="${color}">
            <origin xyz="-0.15 0 0" rpy="0 -${PI/4} 0"/>
            <box size="${tail_length} ${tail_width} ${tail_height}"/>
            <inertia ixx="0.1" ixy="0.0" ixz="0.0" 
                     iyy="0.1" iyz="0.0" 
                     izz="0.1"/>
        </xacro:rigid_shape> -->
  <!-- <link name="${name}_link">

            <visual>
                <origin xyz="-${tail_length/2} 0 0" rpy="0 0 0"/>
                <geometry>
                    <box size="${tail_length} ${tail_width} ${tail_height}"/>
                </geometry>
                <material name="color"/>
            </visual>

            <collision>
                <origin xyz="-${tail_length/2} 0 0" rpy="0 0 0"/>
                <geometry>
                    <box size="${tail_length} ${tail_width} ${tail_height}"/>
                </geometry>
            </collision>

            <inertial>
                <origin xyz="-${tail_length/2} 0 0" rpy="0 0 0"/>
                <mass value="${tail_mass}"/>
                <inertia ixx="0.1" ixy="0.0" ixz="0.0" 
                         iyy="0.1" iyz="0.0" 
                         izz="0.1"/>
            </inertial>

        </link> -->
  <!-- Left Leg Links -->
  <!-- hip mounting points -->
  <joint name="left_hip_mount_joint" type="fixed">
    <origin rpy="0 0 0" xyz="0.0 0.119 -0.147"/>
    <parent link="base_link"/>
    <child link="left_hip_yaw_link"/>
  </joint>
  <!-- hip yaw -->
  <!-- <xacro:rigid_shape name="${prefix}_hip_yaw_link" mass="${hip_joint_mass}" color="yellow-skin">
            <origin xyz="0 0 0" rpy="0 0 0"/>
            <cylinder radius="${hip_joint_radius}" length="${hip_joint_length}"/>
            <inertia ixx="0.1" ixy="0.0" ixz="0.0" 
                     iyy="0.1" iyz="0.0" 
                     izz="0.1"/>
        </xacro:rigid_shape> -->
  <link name="left_hip_yaw_link">
    <visual>
      <origin rpy="0 0 0" xyz="0 0 0"/>
      <geometry>
        <mesh filename="../meshes/wheelwalker_v0.1/left_hip_yaw_link.stl" scale="0.001 0.001 0.001"/>
      </geometry>
      <material name="">   
        <color rgba="0.6 0.6 0.6 1.0"/>
      </material>
    </visual>

    <collision>
      <origin rpy="0 0 0" xyz="0 0 0"/>
      <geometry>
        <cylinder length="0.08879999999999999" radius="0.0185"/>
      </geometry>
    </collision>
    <inertial>
      <origin rpy="0 0 0" xyz="0 0 0"/>
      <mass value="0.85"/>
      <inertia ixx="0.0006312801249999998" ixy="0.0" ixz="0.0" iyy="0.0006312801249999998" iyz="0.0" izz="0.00014545624999999997"/>
    </inertial>
    <!-- <xacro:insert_block name="inertial"/> -->
  </link>
  <joint name="left_hip_yaw_joint" type="fixed">
    <origin rpy="0 0 0" xyz="0 0 0"/>
    <parent link="left_hip_yaw_link"/>
    <child link="left_hip_roll_link"/>
    <axis xyz="0 0 1"/>
    <limit effort="1000.0" lower="-3.14159265359" upper="3.14159265359" velocity="10.0"/>
    <dynamics damping="0.0" friction="0.0"/>
  </joint>
  <!-- hip roll -->
  <!-- <xacro:rigid_shape name="${prefix}_hip_roll_link" mass="${hip_joint_mass}" color="yellow-skin">
            <origin xyz="0 0 0" rpy="${hip_roll_offset_rpy}"/>
            <cylinder radius="${hip_joint_radius}" length="${hip_joint_length}"/>
            <inertia ixx="0.1" ixy="0.0" ixz="0.0" 
                     iyy="0.1" iyz="0.0" 
                     izz="0.1"/>
        </xacro:rigid_shape> -->
  <link name="left_hip_roll_link">
    <visual>
      <origin rpy="0 0 0" xyz="0 0 0.08175"/>
      <geometry>
        <mesh filename="../meshes/wheelwalker_v0.1/left_hip_roll_link.stl" scale="0.001 0.001 0.001"/>
      </geometry>
      <material name="">   
        <color rgba="0.6 0.6 0.6 1.0"/>
      </material>
    </visual>

    <collision>
      <origin rpy="0 1.570796326795 0" xyz="0 0 0.08175"/>
      <geometry>
        <cylinder length="0.08879999999999999" radius="0.0185"/>
      </geometry>
    </collision>
    <inertial>
      <origin rpy="0 1.570796326795 0" xyz="0 0 0.08175"/>
      <mass value="0.85"/>
      <inertia ixx="0.0006312801249999998" ixy="0.0" ixz="0.0" iyy="0.0006312801249999998" iyz="0.0" izz="0.00014545624999999997"/>
    </inertial>
    <!-- <xacro:insert_block name="inertial"/> -->
  </link>
  <joint name="left_hip_roll_joint" type="fixed">
    <origin rpy="0 0 0" xyz="0 0 0.08175"/>
    <parent link="left_hip_roll_link"/>
    <child link="left_hip_pitch_link"/>
    <axis xyz="1 0 0"/>
    <limit effort="1000.0" lower="-3.14159265359" upper="3.14159265359" velocity="10.0"/>
    <dynamics damping="0.0" friction="0.0"/>
  </joint>
  <!-- hip pitch -->
  <!-- <xacro:rigid_shape name="${prefix}_hip_pitch_link" mass="${hip_joint_mass}" color="yellow-skin">
            <origin xyz="0 0 0" rpy="${hip_pitch_offset_rpy}"/>
            <cylinder radius="${hip_joint_radius}" length="${hip_joint_length}"/>
            <inertia ixx="0.1" ixy="0.0" ixz="0.0" 
                     iyy="0.1" iyz="0.0" 
                     izz="0.1"/>
        </xacro:rigid_shape> -->
  <link name="left_hip_pitch_link">
    <visual>
      <origin rpy="0 0 0" xyz="0 0.07525 0"/>
      <geometry>
        <mesh filename="../meshes/wheelwalker_v0.1/left_hip_pitch_link.stl" scale="0.001 0.001 0.001"/>
      </geometry>
      <material name="">   
        <color rgba="0.6 0.6 0.6 1.0"/>
      </material>
    </visual>

    <collision>
      <origin rpy="1.570796326795 0 0" xyz="0 0.07525 0"/>
      <geometry>
        <cylinder length="0.08879999999999999" radius="0.0185"/>
      </geometry>
    </collision>
    <inertial>
      <origin rpy="1.570796326795 0 0" xyz="0 0.07525 0"/>
      <mass value="0.85"/>
      <inertia ixx="0.0006312801249999998" ixy="0.0" ixz="0.0" iyy="0.0006312801249999998" iyz="0.0" izz="0.00014545624999999997"/>
    </inertial>
    <!-- <xacro:insert_block name="inertial"/> -->
  </link>
  <joint name="left_hip_pitch_joint" type="revolute">
    <origin rpy="0 0.7853981633975 0" xyz="0 0.07525 0"/>
    <parent link="left_hip_pitch_link"/>
    <child link="left_thigh_link"/>
    <axis xyz="0 1 0"/>
    <limit effort="1000.0" lower="-2.3561944901925003" upper="1.570796326795" velocity="10.0"/>
    <dynamics damping="0.0" friction="0.0"/>
  </joint>
  <!-- Thigh link -->
  <!-- <joint name="${prefix}_thigh_mount_joint" type="fixed">
            <origin xyz="0 0 0" rpy="0 0 0"/>
            <parent link="${prefix}_hip_pitch_link"/>
            <child link="${prefix}_thigh_link"/>
        </joint> -->
  <!-- <xacro:rigid_shape name="${prefix}_thigh_link" mass="${thigh_mass}" color="${color}">
            <origin xyz="0 0 -${thigh_length/2}" rpy="${thigh_mount_rpy}"/>
            <cylinder length="${thigh_length}" radius="${thigh_radius}"/>
            <inertia ixx="0.1" ixy="0.0" ixz="0.0" 
                     iyy="0.1" iyz="0.0" 
                     izz="0.1" />
        </xacro:rigid_shape> -->
  <link name="left_thigh_link">
    <visual>
      <origin rpy="0 0 0" xyz="0 0 0"/>
      <geometry>
        <mesh filename="../meshes/wheelwalker_v0.1/left_thigh_link.stl" scale="0.001 0.001 0.001"/>
      </geometry>
      <material name="">   
        <color rgba="0.6 0.6 0.6 1.0"/>
      </material>
    </visual>

    <collision>
      <origin rpy="0 0 0" xyz="0.0 0.0 -0.125"/>
      <geometry>
        <cylinder length="0.25" radius="0.033"/>
      </geometry>
    </collision>
    <inertial>
      <origin rpy="0 0 0" xyz="0.0 0.0 -0.125"/>
      <mass value="2.8"/>
      <inertia ixx="0.015345633333333332" ixy="0.0" ixz="0.0" iyy="0.015345633333333332" iyz="0.0" izz="0.0015246"/>
    </inertial>
    <!-- <xacro:insert_block name="inertial"/> -->
  </link>
  <!-- knee mount -->
  <!-- <joint name="${prefix}_knee_mount_joint" type="fixed">
            <origin xyz="${knee_mount_x} ${knee_mount_y} ${knee_mount_z}" rpy="0 0 0"/>
            <parent link="${prefix}_thigh_link"/>
            <child link="${prefix}_knee_mount_link"/>
        </joint> -->
  <!-- <xacro:virtual_shape name="${prefix}_knee_mount_link" color="yellow-skin">
            <origin xyz="0 0 0" rpy="${knee_mount_rpy}"/>
            <cylinder radius="${mount_radius_knee}" length="${mount_length_knee}"/>
        </xacro:virtual_shape> -->
  <!-- <xacro:rigid_shape name="${prefix}_knee_mount_link" mass="${hip_joint_mass}" color="yellow-skin">
            <origin xyz="0 0 0" rpy="${knee_mount_rpy}"/>
            <cylinder radius="${mount_radius_knee}" length="${mount_length_knee}"/>
            <inertia ixx="0.1" ixy="0.0" ixz="0.0" 
                     iyy="0.1" iyz="0.0" 
                     izz="0.1"/>
        </xacro:rigid_shape> -->
  <!-- <xacro:joint_mount name="${prefix}_knee_mount"
                           parent_link="${prefix}_thigh_link"
                           attachment_origin="0 0 -${thigh_length}"
                           attachment_rotation="0 0 ${PI/2}"
                           radius_knee="${mount_radius_knee}"
                           length_knee="${mount_length_knee}"
                           color="yellow-skin"/>         -->
  <joint name="left_knee_pitch_joint" type="revolute">
    <!-- <origin xyz="${attachment_origin}" rpy="${attachment_rotation}"/> -->
    <origin rpy="0 -1.570796326795 0 " xyz="0.04 0 -0.25"/>
    <parent link="left_thigh_link"/>
    <child link="left_tibia_link"/>
    <axis xyz="0 1 0"/>
    <limit effort="1000.0" lower="-0.7853981633975" upper="2.3561944901925003" velocity="10.0"/>
    <dynamics damping="0.0" friction="0.0"/>
  </joint>
  <!-- <xacro:rigid_shape name="${prefix}_tibia_link" mass="${tibia_mass}" color="${color}">
            <origin xyz="0 0 -${tibia_length/2 + mount_radius_knee}" rpy="0 0 0"/>
            <cylinder radius="${tibia_radius}" length="${tibia_length}"/>
            <inertia ixx="0.1" ixy="0.0" ixz="0.0" 
                     iyy="0.1" iyz="0.0" 
                     izz="0.1"/>
        </xacro:rigid_shape> -->
  <link name="left_tibia_link">
    <visual>
      <origin rpy="0 0 0" xyz="0 0 0"/>
      <geometry>
        <mesh filename="../meshes/wheelwalker_v0.1/left_tibia_link.stl" scale="0.001 0.001 0.001"/>
      </geometry>
      <material name="">   
        <color rgba="0.6 0.6 0.6 1.0"/>
      </material>
    </visual>

    <collision>
      <origin rpy="0 0 0" xyz="0 0 -0.125"/>
      <geometry>
        <cylinder length="0.25" radius="0.0315"/>
      </geometry>
    </collision>
    <inertial>
      <origin rpy="0 0 0" xyz="0 0 -0.125"/>
      <mass value="1.2"/>
      <inertia ixx="0.006547674999999999" ixy="0.0" ixz="0.0" iyy="0.006547674999999999" iyz="0.0" izz="0.00059535"/>
    </inertial>
    <!-- <xacro:insert_block name="inertial"/> -->
  </link>
  <!-- add ankle mount -->
  <!-- <joint name="${prefix}_ankle_mount_joint" type="fixed">
            <origin xyz="${ankle_mount_x} ${ankle_mount_y} ${ankle_mount_z}" rpy="0 0 0"/>
            <parent link="${prefix}_tibia_link"/>
            <child link="${prefix}_ankle_mount_link"/>
        </joint> -->
  <!-- <xacro:rigid_shape name="${prefix}_ankle_mount_link" mass="${tibia_mass}" color="yellow-skin">
            <origin xyz="0 0 0" rpy="${ankle_mount_rpy}"/>
            <cylinder radius="${mount_radius_ankle}" length="${mount_length_ankle}"/>
            <inertia ixx="0.1" ixy="0.0" ixz="0.0" 
                     iyy="0.1" iyz="0.0" 
                     izz="0.1"/>
        </xacro:rigid_shape> -->
  <!-- <xacro:joint_mount name="${prefix}_ankle_mount"
                           parent_link="${prefix}_tibia_link"
                           attachment_origin="0 0 -${tibia_length}"
                           attachment_rotation="0 0 0"
                           mount_radius="${mount_radius_ankle}"
                           mount_length="${mount_length_ankle}"
                           color="yellow-skin"/> -->
  <!-- supporting foot -->
  <joint name="left_ankle_pitch_joint" type="fixed">
    <origin rpy="0 0.5235987755983333 0" xyz="0 -0.035 -0.25"/>
    <parent link="left_tibia_link"/>
    <child link="left_foot_link"/>
    <axis xyz="0 1 0"/>
    <limit effort="1000.0" lower="-0.7853981633975" upper="0.7853981633975" velocity="10.0"/>
    <dynamics damping="0.0" friction="0.0"/>
  </joint>
  <!-- <xacro:rigid_shape name="${prefix}_foot_link" mass="${foot_mass}" color="${color}">
            <origin xyz="${foot_shape_x} ${foot_shape_y * reflect} ${foot_shape_z}" 
                    rpy="${foot_shape_rpy}"/>
            <cylinder radius="${foot_radius}" length="${foot_length}"/>
            <inertia ixx="0.1" ixy="0.0" ixz="0.0" 
                     iyy="0.1" iyz="0.0" 
                     izz="0.1"/>
        </xacro:rigid_shape> -->
  <link name="left_foot_link">
    <visual>
      <origin rpy="0 0 0" xyz="0 0 0"/>
      <geometry>
        <mesh filename="../meshes/wheelwalker_v0.1/left_foot_link.stl" scale="0.001 0.001 0.001"/>
      </geometry>
      <material name="">   
        <color rgba="0.6 0.6 0.6 1.0"/>
      </material>
    </visual>

    <collision>
      <origin rpy="0 1.570796326795 0" xyz="-0.09 0 0"/>
      <geometry>
        <cylinder length="0.18" radius="0.012"/>
      </geometry>
    </collision>
    <inertial>
      <origin rpy="0 1.570796326795 0" xyz="-0.09 0 0"/>
      <mass value="1.177"/>
      <inertia ixx="0.0032202719999999997" ixy="0.0" ixz="0.0" iyy="0.0032202719999999997" iyz="0.0" izz="8.4744e-05"/>
    </inertial>
    <!-- <xacro:insert_block name="inertial"/> -->
  </link>
  <!-- wheel link -->
  <joint name="left_wheel_joint" type="continuous">
    <origin rpy="0 0 0" xyz="0 0.03 -0.25"/>
    <parent link="left_tibia_link"/>
    <child link="left_wheel_link"/>
    <axis xyz="0 1 0"/>
    <limit effort="1000.0" velocity="10.0"/>
    <dynamics damping="0.0" friction="0.0"/>
  </joint>
  <!-- <xacro:rigid_shape name="${prefix}_wheel_link" mass="${wheel_mass}" color="${color}">
            <origin xyz="${wheel_shape_x} ${wheel_shape_y * reflect} ${wheel_shape_z}" 
                    rpy="${wheel_shape_rpy}"/>
            <cylinder radius="${wheel_radius}" length="${wheel_length}"/>
            <inertia ixx="0.1" ixy="0.0" ixz="0.0" 
                     iyy="0.1" iyz="0.0" 
                     izz="0.1"/>
        </xacro:rigid_shape> -->
  <link name="left_wheel_link">
    <visual>
      <origin rpy="0 0 0" xyz="0 0 0"/>
      <geometry>
        <mesh filename="../meshes/wheelwalker_v0.1/left_wheel_link.stl" scale="0.001 0.001 0.001"/>
      </geometry>
      <material name="">   
        <color rgba="0.6 0.6 0.6 1.0"/>
      </material>
    </visual>

    <collision>
      <origin rpy="1.570796326795 0 0" xyz="0 0 0"/>
      <geometry>
        <cylinder length="0.03" radius="0.11"/>
      </geometry>
    </collision>
    <inertial>
      <origin rpy="1.570796326795 0 0" xyz="0 0 0"/>
      <mass value="0.9"/>
      <inertia ixx="0.0027899999999999995" ixy="0.0" ixz="0.0" iyy="0.0027899999999999995" iyz="0.0" izz="0.005445"/>
    </inertial>
    <!-- <xacro:insert_block name="inertial"/> -->
  </link>
  <!-- Right Leg Links -->
  <!-- hip mounting points -->
  <joint name="right_hip_mount_joint" type="fixed">
    <origin rpy="0 0 0" xyz="0.0 -0.119 -0.147"/>
    <parent link="base_link"/>
    <child link="right_hip_yaw_link"/>
  </joint>
  <!-- hip yaw -->
  <!-- <xacro:rigid_shape name="${prefix}_hip_yaw_link" mass="${hip_joint_mass}" color="yellow-skin">
            <origin xyz="0 0 0" rpy="0 0 0"/>
            <cylinder radius="${hip_joint_radius}" length="${hip_joint_length}"/>
            <inertia ixx="0.1" ixy="0.0" ixz="0.0" 
                     iyy="0.1" iyz="0.0" 
                     izz="0.1"/>
        </xacro:rigid_shape> -->
  <link name="right_hip_yaw_link">
    <visual>
      <origin rpy="0 0 0" xyz="0 0 0"/>
      <geometry>
        <mesh filename="../meshes/wheelwalker_v0.1/right_hip_yaw_link.stl" scale="0.001 0.001 0.001"/>
      </geometry>
      <material name="">   
        <color rgba="0.6 0.6 0.6 1.0"/>
      </material>
    </visual>

    <collision>
      <origin rpy="0 0 0" xyz="0 0 0"/>
      <geometry>
        <cylinder length="0.08879999999999999" radius="0.0185"/>
      </geometry>
    </collision>
    <inertial>
      <origin rpy="0 0 0" xyz="0 0 0"/>
      <mass value="0.85"/>
      <inertia ixx="0.0006312801249999998" ixy="0.0" ixz="0.0" iyy="0.0006312801249999998" iyz="0.0" izz="0.00014545624999999997"/>
    </inertial>
    <!-- <xacro:insert_block name="inertial"/> -->
  </link>
  <joint name="right_hip_yaw_joint" type="fixed">
    <origin rpy="0 0 0" xyz="0 0 0"/>
    <parent link="right_hip_yaw_link"/>
    <child link="right_hip_roll_link"/>
    <axis xyz="0 0 1"/>
    <limit effort="1000.0" lower="-3.14159265359" upper="3.14159265359" velocity="10.0"/>
    <dynamics damping="0.0" friction="0.0"/>
  </joint>
  <!-- hip roll -->
  <!-- <xacro:rigid_shape name="${prefix}_hip_roll_link" mass="${hip_joint_mass}" color="yellow-skin">
            <origin xyz="0 0 0" rpy="${hip_roll_offset_rpy}"/>
            <cylinder radius="${hip_joint_radius}" length="${hip_joint_length}"/>
            <inertia ixx="0.1" ixy="0.0" ixz="0.0" 
                     iyy="0.1" iyz="0.0" 
                     izz="0.1"/>
        </xacro:rigid_shape> -->
  <link name="right_hip_roll_link">
    <visual>
      <origin rpy="0 0 0" xyz="0 0 0.08175"/>
      <geometry>
        <mesh filename="../meshes/wheelwalker_v0.1/right_hip_roll_link.stl" scale="0.001 0.001 0.001"/>
      </geometry>
      <material name="">   
        <color rgba="0.6 0.6 0.6 1.0"/>
      </material>
    </visual>

    <collision>
      <origin rpy="0 1.570796326795 0" xyz="0 0 0.08175"/>
      <geometry>
        <cylinder length="0.08879999999999999" radius="0.0185"/>
      </geometry>
    </collision>
    <inertial>
      <origin rpy="0 1.570796326795 0" xyz="0 0 0.08175"/>
      <mass value="0.85"/>
      <inertia ixx="0.0006312801249999998" ixy="0.0" ixz="0.0" iyy="0.0006312801249999998" iyz="0.0" izz="0.00014545624999999997"/>
    </inertial>
    <!-- <xacro:insert_block name="inertial"/> -->
  </link>
  <joint name="right_hip_roll_joint" type="fixed">
    <origin rpy="0 0 0" xyz="0 0 0.08175"/>
    <parent link="right_hip_roll_link"/>
    <child link="right_hip_pitch_link"/>
    <axis xyz="-1 0 0"/>
    <limit effort="1000.0" lower="-3.14159265359" upper="3.14159265359" velocity="10.0"/>
    <dynamics damping="0.0" friction="0.0"/>
  </joint>
  <!-- hip pitch -->
  <!-- <xacro:rigid_shape name="${prefix}_hip_pitch_link" mass="${hip_joint_mass}" color="yellow-skin">
            <origin xyz="0 0 0" rpy="${hip_pitch_offset_rpy}"/>
            <cylinder radius="${hip_joint_radius}" length="${hip_joint_length}"/>
            <inertia ixx="0.1" ixy="0.0" ixz="0.0" 
                     iyy="0.1" iyz="0.0" 
                     izz="0.1"/>
        </xacro:rigid_shape> -->
  <link name="right_hip_pitch_link">
    <visual>
      <origin rpy="0 0 0" xyz="0 -0.07525 0"/>
      <geometry>
        <mesh filename="../meshes/wheelwalker_v0.1/right_hip_pitch_link.stl" scale="0.001 0.001 0.001"/>
      </geometry>
      <material name="">   
        <color rgba="0.6 0.6 0.6 1.0"/>
      </material>
    </visual>

    <collision>
      <origin rpy="1.570796326795 0 0" xyz="0 -0.07525 0"/>
      <geometry>
        <cylinder length="0.08879999999999999" radius="0.0185"/>
      </geometry>
    </collision>
    <inertial>
      <origin rpy="1.570796326795 0 0" xyz="0 -0.07525 0"/>
      <mass value="0.85"/>
      <inertia ixx="0.0006312801249999998" ixy="0.0" ixz="0.0" iyy="0.0006312801249999998" iyz="0.0" izz="0.00014545624999999997"/>
    </inertial>
    <!-- <xacro:insert_block name="inertial"/> -->
  </link>
  <joint name="right_hip_pitch_joint" type="revolute">
    <origin rpy="0 0.7853981633975 0" xyz="0 -0.07525 0"/>
    <parent link="right_hip_pitch_link"/>
    <child link="right_thigh_link"/>
    <axis xyz="0 1 0"/>
    <limit effort="1000.0" lower="-2.3561944901925003" upper="1.570796326795" velocity="10.0"/>
    <dynamics damping="0.0" friction="0.0"/>
  </joint>
  <!-- Thigh link -->
  <!-- <joint name="${prefix}_thigh_mount_joint" type="fixed">
            <origin xyz="0 0 0" rpy="0 0 0"/>
            <parent link="${prefix}_hip_pitch_link"/>
            <child link="${prefix}_thigh_link"/>
        </joint> -->
  <!-- <xacro:rigid_shape name="${prefix}_thigh_link" mass="${thigh_mass}" color="${color}">
            <origin xyz="0 0 -${thigh_length/2}" rpy="${thigh_mount_rpy}"/>
            <cylinder length="${thigh_length}" radius="${thigh_radius}"/>
            <inertia ixx="0.1" ixy="0.0" ixz="0.0" 
                     iyy="0.1" iyz="0.0" 
                     izz="0.1" />
        </xacro:rigid_shape> -->
  <link name="right_thigh_link">
    <visual>
      <origin rpy="0 0 0" xyz="0 0 0"/>
      <geometry>
        <mesh filename="../meshes/wheelwalker_v0.1/right_thigh_link.stl" scale="0.001 0.001 0.001"/>
      </geometry>
      <material name="">   
        <color rgba="0.6 0.6 0.6 1.0"/>
      </material>
    </visual>

    <collision>
      <origin rpy="0 0 0" xyz="0.0 -0.0 -0.125"/>
      <geometry>
        <cylinder length="0.25" radius="0.033"/>
      </geometry>
    </collision>
    <inertial>
      <origin rpy="0 0 0" xyz="0.0 -0.0 -0.125"/>
      <mass value="2.8"/>
      <inertia ixx="0.015345633333333332" ixy="0.0" ixz="0.0" iyy="0.015345633333333332" iyz="0.0" izz="0.0015246"/>
    </inertial>
    <!-- <xacro:insert_block name="inertial"/> -->
  </link>
  <!-- knee mount -->
  <!-- <joint name="${prefix}_knee_mount_joint" type="fixed">
            <origin xyz="${knee_mount_x} ${knee_mount_y} ${knee_mount_z}" rpy="0 0 0"/>
            <parent link="${prefix}_thigh_link"/>
            <child link="${prefix}_knee_mount_link"/>
        </joint> -->
  <!-- <xacro:virtual_shape name="${prefix}_knee_mount_link" color="yellow-skin">
            <origin xyz="0 0 0" rpy="${knee_mount_rpy}"/>
            <cylinder radius="${mount_radius_knee}" length="${mount_length_knee}"/>
        </xacro:virtual_shape> -->
  <!-- <xacro:rigid_shape name="${prefix}_knee_mount_link" mass="${hip_joint_mass}" color="yellow-skin">
            <origin xyz="0 0 0" rpy="${knee_mount_rpy}"/>
            <cylinder radius="${mount_radius_knee}" length="${mount_length_knee}"/>
            <inertia ixx="0.1" ixy="0.0" ixz="0.0" 
                     iyy="0.1" iyz="0.0" 
                     izz="0.1"/>
        </xacro:rigid_shape> -->
  <!-- <xacro:joint_mount name="${prefix}_knee_mount"
                           parent_link="${prefix}_thigh_link"
                           attachment_origin="0 0 -${thigh_length}"
                           attachment_rotation="0 0 ${PI/2}"
                           radius_knee="${mount_radius_knee}"
                           length_knee="${mount_length_knee}"
                           color="yellow-skin"/>         -->
  <joint name="right_knee_pitch_joint" type="revolute">
    <!-- <origin xyz="${attachment_origin}" rpy="${attachment_rotation}"/> -->
    <origin rpy="0 -1.570796326795 0 " xyz="0.04 0 -0.25"/>
    <parent link="right_thigh_link"/>
    <child link="right_tibia_link"/>
    <axis xyz="0 1 0"/>
    <limit effort="1000.0" lower="-0.7853981633975" upper="2.3561944901925003" velocity="10.0"/>
    <dynamics damping="0.0" friction="0.0"/>
  </joint>
  <!-- <xacro:rigid_shape name="${prefix}_tibia_link" mass="${tibia_mass}" color="${color}">
            <origin xyz="0 0 -${tibia_length/2 + mount_radius_knee}" rpy="0 0 0"/>
            <cylinder radius="${tibia_radius}" length="${tibia_length}"/>
            <inertia ixx="0.1" ixy="0.0" ixz="0.0" 
                     iyy="0.1" iyz="0.0" 
                     izz="0.1"/>
        </xacro:rigid_shape> -->
  <link name="right_tibia_link">
    <visual>
      <origin rpy="0 0 0" xyz="0 0 0"/>
      <geometry>
        <mesh filename="../meshes/wheelwalker_v0.1/right_tibia_link.stl" scale="0.001 0.001 0.001"/>
      </geometry>
      <material name="">   
        <color rgba="0.6 0.6 0.6 1.0"/>
      </material>
    </visual>

    <collision>
      <origin rpy="0 0 0" xyz="0 0 -0.125"/>
      <geometry>
        <cylinder length="0.25" radius="0.0315"/>
      </geometry>
    </collision>
    <inertial>
      <origin rpy="0 0 0" xyz="0 0 -0.125"/>
      <mass value="1.2"/>
      <inertia ixx="0.006547674999999999" ixy="0.0" ixz="0.0" iyy="0.006547674999999999" iyz="0.0" izz="0.00059535"/>
    </inertial>
    <!-- <xacro:insert_block name="inertial"/> -->
  </link>
  <!-- add ankle mount -->
  <!-- <joint name="${prefix}_ankle_mount_joint" type="fixed">
            <origin xyz="${ankle_mount_x} ${ankle_mount_y} ${ankle_mount_z}" rpy="0 0 0"/>
            <parent link="${prefix}_tibia_link"/>
            <child link="${prefix}_ankle_mount_link"/>
        </joint> -->
  <!-- <xacro:rigid_shape name="${prefix}_ankle_mount_link" mass="${tibia_mass}" color="yellow-skin">
            <origin xyz="0 0 0" rpy="${ankle_mount_rpy}"/>
            <cylinder radius="${mount_radius_ankle}" length="${mount_length_ankle}"/>
            <inertia ixx="0.1" ixy="0.0" ixz="0.0" 
                     iyy="0.1" iyz="0.0" 
                     izz="0.1"/>
        </xacro:rigid_shape> -->
  <!-- <xacro:joint_mount name="${prefix}_ankle_mount"
                           parent_link="${prefix}_tibia_link"
                           attachment_origin="0 0 -${tibia_length}"
                           attachment_rotation="0 0 0"
                           mount_radius="${mount_radius_ankle}"
                           mount_length="${mount_length_ankle}"
                           color="yellow-skin"/> -->
  <!-- supporting foot -->
  <joint name="right_ankle_pitch_joint" type="fixed">
    <origin rpy="0 0.5235987755983333 0" xyz="0 0.035 -0.25"/>
    <parent link="right_tibia_link"/>
    <child link="right_foot_link"/>
    <axis xyz="0 1 0"/>
    <limit effort="1000.0" lower="-0.7853981633975" upper="0.7853981633975" velocity="10.0"/>
    <dynamics damping="0.0" friction="0.0"/>
  </joint>
  <!-- <xacro:rigid_shape name="${prefix}_foot_link" mass="${foot_mass}" color="${color}">
            <origin xyz="${foot_shape_x} ${foot_shape_y * reflect} ${foot_shape_z}" 
                    rpy="${foot_shape_rpy}"/>
            <cylinder radius="${foot_radius}" length="${foot_length}"/>
            <inertia ixx="0.1" ixy="0.0" ixz="0.0" 
                     iyy="0.1" iyz="0.0" 
                     izz="0.1"/>
        </xacro:rigid_shape> -->
  <link name="right_foot_link">
    <visual>
      <origin rpy="0 0 0" xyz="0 0 0"/>
      <geometry>
        <mesh filename="../meshes/wheelwalker_v0.1/right_foot_link.stl" scale="0.001 0.001 0.001"/>
      </geometry>
      <material name="">   
        <color rgba="0.6 0.6 0.6 1.0"/>
      </material>
    </visual>

    <collision>
      <origin rpy="0 1.570796326795 0" xyz="-0.09 0 0"/>
      <geometry>
        <cylinder length="0.18" radius="0.012"/>
      </geometry>
    </collision>
    <inertial>
      <origin rpy="0 1.570796326795 0" xyz="-0.09 0 0"/>
      <mass value="1.177"/>
      <inertia ixx="0.0032202719999999997" ixy="0.0" ixz="0.0" iyy="0.0032202719999999997" iyz="0.0" izz="8.4744e-05"/>
    </inertial>
    <!-- <xacro:insert_block name="inertial"/> -->
  </link>
  <!-- wheel link -->
  <joint name="right_wheel_joint" type="continuous">
    <origin rpy="0 0 0" xyz="0 -0.03 -0.25"/>
    <parent link="right_tibia_link"/>
    <child link="right_wheel_link"/>
    <axis xyz="0 1 0"/>
    <limit effort="1000.0" velocity="10.0"/>
    <dynamics damping="0.0" friction="0.0"/>
  </joint>
  <!-- <xacro:rigid_shape name="${prefix}_wheel_link" mass="${wheel_mass}" color="${color}">
            <origin xyz="${wheel_shape_x} ${wheel_shape_y * reflect} ${wheel_shape_z}" 
                    rpy="${wheel_shape_rpy}"/>
            <cylinder radius="${wheel_radius}" length="${wheel_length}"/>
            <inertia ixx="0.1" ixy="0.0" ixz="0.0" 
                     iyy="0.1" iyz="0.0" 
                     izz="0.1"/>
        </xacro:rigid_shape> -->
  <link name="right_wheel_link">
    <visual>
      <origin rpy="0 0 0" xyz="0 0 0"/>
      <geometry>
        <mesh filename="../meshes/wheelwalker_v0.1/right_wheel_link.stl" scale="0.001 0.001 0.001"/>
      </geometry>
      <material name="">   
        <color rgba="0.6 0.6 0.6 1.0"/>
      </material>
    </visual>

    <collision>
      <origin rpy="1.570796326795 0 0" xyz="0 0 0"/>
      <geometry>
        <cylinder length="0.03" radius="0.11"/>
      </geometry>
    </collision>
    <inertial>
      <origin rpy="1.570796326795 0 0" xyz="0 0 0"/>
      <mass value="0.9"/>
      <inertia ixx="0.0027899999999999995" ixy="0.0" ixz="0.0" iyy="0.0027899999999999995" iyz="0.0" izz="0.005445"/>
    </inertial>
    <!-- <xacro:insert_block name="inertial"/> -->
  </link>
</robot>

